Workbook

Sheet Inf. Preliminar
C3: INFORME PRELIMINAR
E5: INFORME DE INVESTIGACIÓN DE POSIBLE BROTE DE ETA Y ENFERMEDADES DE ORIGEN HÍDRICO | M5: Logo Institución
E6: INSTITUTO NACIONAL DE SALUD
E7: DIRECCIÓN DE VIGILANCIA Y ANÁLISIS DEL RIESGO EN SALUD PÚBLICA
E8: GRUPO DE GESTIÓN DEL RIESGO RESPUESTA INMEDIATA Y COMUNICACIÓN DEL RIESGO
C12: Departamento
C13: Municipio
C14: Barrio/Corregimiento/Vereda/Localidad
C16: Cumple con parámetros de notificación inmediata? | H16: Si | J16: No
C18: Fecha de inicio del brote (dd/mm/año):
C20: Fecha de detección del brote (dd/mm/año):
C22: Fecha de notificación al SAT (dd/mm/año):
C24: Fecha de notificación al Sivigila (dd/mm/año):
C26: Semana epidemiológica de ocurrencia:
C28: Lugar de ocurrencia:
C30: Dirección: | I30: Teléfono:
C32: Fecha de inicio de signos y síntomas de caso índice (dd/mm/año): | M32: =IF(N34>E34,"Error - el total de casos no puede ser mayor al de expuestos"," ")
C34: Posible número de expuestos | G34: Casos UPGD | J34: Casos (BAC) | M34: Tocal casos | N34: =H34+K34 -> 0
C36: =IF((E38+H38)=$N$34," ","Error - la suma de casos vivos y muertos debe ser igual al total de casos") | J36: =IF((K38+N38)=$N$34," ","Error - la suma de casos hospitalizados y ambu. debe ser igual al total casos")
C38: Casos vivos | G38: Casos muertos | J38: Casos hospitalizados | M38: Casos en casa
C40: Posibles alimentos/agua o mecanismos de transmisión implicados
C42: Signos y síntomas
C44: Antecedentes del brote:
C47: Hipótesis inicial (teniendo en cuenta signos y síntomas):
C49: Medidas iniciales de control:
C51: Observaciones:
C53: Muestras recolectadas | E53: Biológica | H53: Superficies
E54: Alimentos | H54: Manipuladores
C56: Alguno de los alimentos implicados son industrializados? | E56: Si | H56: =IF(F56="x","Datos del fabricante y del/los producto/s"," ")
E57: No
C59: Requiere apoyo de otras instancias? | E59: Si | H59: =IF(F59="x","Cuáles?"," ")
E60: No
C62: Nombre del profesional que elaboró el informe
C63: Nombre y cargo del profesional que revisó
C64: Teléfono o celular
C65: e-mail
J68: Diseñado y elaborado por: Milena Borbón Ramos. DVARSP. Versión Julio 31 de 2022

Sheet Inf. 72 horas
C3: SEGUNDO INFORME - 72 HORAS
E5: INFORME DE INVESTIGACIÓN DE POSIBLE BROTE DE ETA Y ENFERMEDADES DE ORIGEN HÍDRICO | P5: Logo Institución
E6: INSTITUTO NACIONAL DE SALUD
E7: DIRECCIÓN DE VIGILANCIA Y ANÁLISIS DEL RIESGO EN SALUD PÚBLICA
E8: GRUPO DE GESTIÓN DEL RIESGO RESPUESTA INMEDIATA Y COMUNICACIÓN DEL RIESGO
E10: ='Inf. Preliminar'!E10 -> 0
C12: Departamento | F12: ='Inf. Preliminar'!F12 -> 0
C13: Municipio | F13: ='Inf. Preliminar'!F13 -> 0
C14: Barrio/Corregimiento/Vereda | F14: ='Inf. Preliminar'!F14 -> 0
C16: Fecha de notificación de investigación epidemiologica de campo (dd/mm/año):
C19: Lugar de ocurrencia: | E19: ='Inf. Preliminar'!E28 -> 0
C22: Definición de caso (basada en alimentos implicados, signos y síntomas y lugar de consumo)
C24: Manejo y tratamiento clínico de los casos, indicar complicaciones
C26: DESCRIPCIÓN DEL BROTE
C28: 1. Distribución de casos por signos y síntomas presentados
C30: Fecha primer caso (dd/mm/año) | J30: Total de casos | M30: Total de expuestos | P30: =IF(K30<=N30,"","Error - El total de casos NO puede superar el total de expuestos ")
C31: Fecha último caso (dd/mm/año)
C33: Signos y síntomas | D33: Número de casos con signos y síntomas | F33: Porcentaje (%)
F34: =D34/$K$30 -> #DIV/0! | G34: =IF(D34>$K$30,"Error - recuerde que el número de casos con signos y síntomas no puede ser mayor al total de casos","")
F35: =D35/$K$30 -> #DIV/0! | G35: =IF(D35>$K$30,"Error - recuerde que el número de casos con signos y síntomas no puede ser mayor al total de casos","")
F36: =D36/$K$30 -> #DIV/0! | G36: =IF(D36>$K$30,"Error - recuerde que el número de casos con signos y síntomas no puede ser mayor al total de casos","")
F37: =D37/$K$30 -> #DIV/0! | G37: =IF(D37>$K$30,"Error - recuerde que el número de casos con signos y síntomas no puede ser mayor al total de casos","")
F38: =D38/$K$30 -> #DIV/0! | G38: =IF(D38>$K$30,"Error - recuerde que el número de casos con signos y síntomas no puede ser mayor al total de casos","")
F39: =D39/$K$30 -> #DIV/0! | G39: =IF(D39>$K$30,"Error - recuerde que el número de casos con signos y síntomas no puede ser mayor al total de casos","")
F40: =D40/$K$30 -> #DIV/0! | G40: =IF(D40>$K$30,"Error - recuerde que el número de casos con signos y síntomas no puede ser mayor al total de casos","")
F41: =D41/$K$30 -> #DIV/0! | G41: =IF(D41>$K$30,"Error - recuerde que el número de casos con signos y síntomas no puede ser mayor al total de casos","")
F42: =D42/$K$30 -> #DIV/0! | G42: =IF(D42>$K$30,"Error - recuerde que el número de casos con signos y síntomas no puede ser mayor al total de casos","")
F43: =D43/$K$30 -> #DIV/0! | G43: =IF(D43>$K$30,"Error - recuerde que el número de casos con signos y síntomas no puede ser mayor al total de casos","")
C45: 2. Tasa de ataque por edad y género (fuente: entrevista a consumidores). Se agrupan en intervalos, según características de la población
C47: Grupo de edad | F47: Masculino | I47: Femenino | N47: Total
F48: Número expuestos de sexo masculino | G48: Número de casos masculinos | H48: % enfermos | I48: Número expuestos de sexo femenino | K48: Número de casos femeninos | M48: % enfermos | N48: Total expuestos | O48: Total enfermos | P48: % enfermos
C49: Menor de 1 año | H49: =IF(F49="","",(G49/F49)) | M49: =IF(I49="","",(K49/I49)) | N49: =F49+I49 -> 0 | O49: =G49+K49 -> 0 | P49: =IF(N49=0,"",(O49/N49))
C50: De 1 a 4 años | H50: =IF(F50="","",(G50/F50)) | M50: =IF(I50="","",(K50/I50)) | N50: =F50+I50 -> 0 | O50: =G50+K50 -> 0 | P50: =IF(N50=0,"",(O50/N50))
C51: De 5 a 9 años | H51: =IF(F51="","",(G51/F51)) | M51: =IF(I51="","",(K51/I51)) | N51: =F51+I51 -> 0 | O51: =G51+K51 -> 0 | P51: =IF(N51=0,"",(O51/N51))
C52: De 10 a 19 años | H52: =IF(F52="","",(G52/F52)) | M52: =IF(I52="","",(K52/I52)) | N52: =F52+I52 -> 0 | O52: =G52+K52 -> 0 | P52: =IF(N52=0,"",(O52/N52))
C53: De 20 a 49 años | H53: =IF(F53="","",(G53/F53)) | M53: =IF(I53="","",(K53/I53)) | N53: =F53+I53 -> 0 | O53: =G53+K53 -> 0 | P53: =IF(N53=0,"",(O53/N53))
C54: De 50 a 74 años | H54: =IF(F54="","",(G54/F54)) | M54: =IF(I54="","",(K54/I54)) | N54: =F54+I54 -> 0 | O54: =G54+K54 -> 0 | P54: =IF(N54=0,"",(O54/N54))
C55: De 75 años y más | H55: =IF(F55="","",(G55/F55)) | M55: =IF(I55="","",(K55/I55)) | N55: =F55+I55 -> 0 | O55: =G55+K55 -> 0 | P55: =IF(N55=0,"",(O55/N55))
C56: Total | F56: =SUM(F49:F55) -> 0 | G56: =SUM(G49:G55) -> 0 | H56: =IF(F56=0,"",(G56/F56)) | I56: =SUM(I49:J55) -> 0 | K56: =SUM(K49:L55) -> 0 | M56: =IF(I56=0,"",(K56/I56)) | N56: =F56+I56 -> 0 | O56: =G56+K56 -> 0 | P56: =IF(N56=0,"",(O56/N56))
F57: =IF(F56<G56,"Error - el número de expuestos no puede ser menor al número de casos","") | I57: =IF(I56<K56,"Error - el número de expuestos no puede ser menor al número de casos","") | N57: =IF(N56=N30,"","Error - La suma NO coincide con el número total de expuestos ") | O57: =IF(O56=K30,"","Error - La suma NO coincide con el número total de casos ")
...

Sheet Inf. final
C3: INFORME FINAL
E5: INFORME DE INVESTIGACIÓN DE POSIBLE BROTE DE ETA Y ENFERMEDADES DE ORIGEN HÍDRICO | P5: Logo Institución
E6: INSTITUTO NACIONAL DE SALUD
E7: DIRECCIÓN DE VIGILANCIA Y ANÁLISIS DEL RIESGO EN SALUD PÚBLICA
E8: GRUPO DE GESTIÓN DEL RIESGO RESPUESTA INMEDIATA Y COMUNICACIÓN DEL RIESGO
E10: ='Inf. Preliminar'!E10 -> 0
C12: Departamento | F12: ='Inf. Preliminar'!F12 -> 0
C13: Municipio | F13: ='Inf. Preliminar'!F13 -> 0
C14: Barrio/Corregimiento/Vereda | F14: ='Inf. Preliminar'!F14 -> 0
C16: Fecha en la que se identificó el agente etiológico (dd/mm/año):
C18: Fecha de cierre del brote (dd/mm/año):
C20: Lugar de ocurrencia: | E20: ='Inf. Preliminar'!E28 -> 0
C23: Total de expuestos | I23: Tocal casos
C25: Casos vivos | F25: Casos muertos | I25: Casos hospitalizados | N25: Casos en casa
C26: =IF((D25+G25)=J23," ","Error - la suma de casos vivos y muertos debe ser igual al total de casos") | I26: =IF((K25+P25)=J23," ","Error - la suma de casos vivos y muertos debe ser igual al total de casos")
C27: Fuente de transmisión | E27: Agua | H27: Contaminación medio ambiental | M27: Modo de transmisión | O27: Oral
E28: Alimentos | H28: Otro - diferente de agua y alimento | O28: Oral - fecal
E29: Persona a persona | H29: Desconocido | O29: Cruzada
C31: Estado del brote | F31: Cerrado CON identificación del agente etiológico | L31: Cerrado SIN identificación del agente etiológico
F32: =IF(I31="X","Cuál(es) fue(ron) el(los) agente(s) identificado(s)"," ")
C34: Resumen de la situación
C37: Descripción del brote
C40: Muestras y Resultados | E40: Tipo de muestra | F40: Biologicas / superficies vivas | N40: Alimentos o superficies inertes
F41: Materia fecal | G41: Vómito | H41: Sangre | I41: Suero sanguíneo | J41: Orina | K41: Líquido cefalorraquideo | L41: Lavado gástrico | M41: Lavado o frotis de manos | N41: Alimento | O41: Restos de alimento | P41: Agua | Q41: Superficie inerte
E43: Agente identificado
C49: Factores determinantes
C51: Seguimiento a puntos criticos
C54: Recomendaciones
C67: Conclusiones
C80: Nombre del profesional que elaboró el informe
C81: Nombre y cargo del profesional que revisó
C82: Teléfono o celular
C83: e-mail
C85: ANEXOS (material de apoyo como gráficas, mapas, figuras, tablas, fotos, etc.)
L90: Diseñado y elaborado por: Milena Borbón Ramos. DVARSP. Versión abril 2021
